<?xml version="1.0" encoding="UTF-8" ?>

<robot xmlns:xacro="http://ros.org/wiki/xacro" name="spider">

    <!-- parameters -->
    <xacro:property name="pi" value="3.1415926535897931"/>
    <xacro:property name="body_length_x" value="0.3556"/>
    <xacro:property name="body_length_y" value="0.165"/>
    <xacro:property name="coxa_length" value="0.052"/>
    <xacro:property name="femur_length" value="0.082"/>
    <xacro:property name="tibia_length" value="0.155"/>

    <gazebo>
        <plugin name="gazebo_ros_control" filename="libgazebo_ros_control.so">
            <robotNamespace>/spider</robotNamespace>
        </plugin>
    </gazebo>

    <link name="base_link"/>
    <joint name="base_joint" type="fixed">
        <parent link="base_link"/>
        <child link="body_link"/>
        <origin xyz="0.0 0.0 -0.7" rpy="0.0 0.0 0.0"/>
    </joint>

    <link name="body_link">
        <visual>
            <origin xyz="0.0 0.0 0.0" rpy="0.0 0.0 0.0"/>
            <geometry>
                <mesh filename="package://spider_description/meshes/xacro/base_link.STL" />
            </geometry>
            <material name="">
                <color rgba="0.7 0.7 0.7 1"/>
            </material>
        </visual>
        <collision>
            <origin xyz="0.0 0.0 0.0" rpy="0.0 0.0 0.0"/>
            <geometry>
                <mesh filename="package://spider_description/meshes/xacro/base_link.STL" />
            </geometry>
            <material name="">
                <color rgba="0.7 0.7 0.7 1"/>
            </material>
        </collision>
        <inertial>
            <origin xyz="0.00053062 0.00014671 0.024203" rpy="0.0 0.0 0.0" />
            <mass value="0.61161"/>
            <inertia
                ixx="0.0045478"
                ixy="-5.8546E-07"
                ixz="5.8091E-06"
                iyy="0.0078405"
                iyz="1.6098E-06"
                izz="0.012139"/>
        </inertial>
    </link>




    <!-- Joint properties -->
    <xacro:property name="joint_lower_limit" value="-2.0"/>
    <xacro:property name="joint_upper_limit" value="2.0"/>
    <xacro:property name="joint_effort" value="6.0"/>
    <xacro:property name="joint_velocity" value="0.524"/>

    <!-- Leg macro -->
    <xacro:macro name="leg" params="side position x y angle axis_femur axis_tibia">

<!-- leg position -->
    <joint name="leg_center_joint_${side}${position}" type="fixed">
        <origin xyz="${x} ${y} 0.0" rpy="0.0 0.0 0.0"/>
        <parent link="body_link"/>
        <child link="leg_center_${side}${position}"/>
    </joint>
    <link name="leg_center_${side}${position}">
        <inertial>
            <origin xyz="0.0 0.0 0.0" rpy="0.0 0.0 0.0" />
            <mass value="0.00001"/>
            <inertia
                ixx="1.0" ixy="0.0"  ixz="0.0"
                iyy="1.0" iyz="0.0"
                izz="1.0" />
        </inertial>
    </link>


    <!-- coxa -->
    <joint name="j_c1_${side}${position}" type="revolute">
        <origin xyz="0.0 0.0 0.0" rpy="0.0 0.0 ${angle}"/>
        <parent link="leg_center_${side}${position}"/>
        <child link="link_c1_${side}${position}"/>
        <axis xyz="0.0 0.0 1.0"/>
        <limit lower="${joint_lower_limit}" upper="${joint_upper_limit}" effort="${joint_effort}" velocity="${joint_velocity}"/>
    </joint>


    <transmission name="t_c1_${side}${position}">
        <type>transmission_interface/SimpleTransmission</type>
        <joint name="j_c1_${side}${position}">
            <hardwareInterface>EffortJointInterface</hardwareInterface>
        </joint>
        <actuator name="m_c1_${side}${position}">
            <hardwareInterface>EffortJointInterface</hardwareInterface>
            <mechanicalReduction>1</mechanicalReduction>
        </actuator>
    </transmission>


    <link name="link_c1_${side}${position}">
        <visual>
            <origin xyz="0.0 0.0 0.0" rpy="0.0 0.0 0.0"/>
            <geometry>
                <mesh filename="package://spider_description/meshes/xacro/link_c1_rm.STL" />
            </geometry>
            <material name="">
                <color rgba="0.7 0.7 0.7 1"/>
            </material>
        </visual>
        <collision>
            <origin xyz="0.0 0.0 0.0" rpy="0.0 0.0 0.0" />
            <geometry>
                <mesh filename="package://spider_description/meshes/xacro/link_c1_rm.STL" />
            </geometry>
            <material name="">
                <color rgba="0.7 0.7 0.7 1" />
            </material>
        </collision>
        <inertial>
            <origin xyz="0.0259999991636717 -5.48568285324569E-07 -0.0238994498902422" rpy="0.0 0.0 0.0" />
            <mass value="0.020733"/>
            <inertia
                ixx="7.1297E-06"
                ixy="4.048E-11"
                ixz="4.2078E-11"
                iyy="7.0574E-06"
                iyz="-7.4454E-15"
                izz="7.0574E-06" />
        </inertial>
    </link>


    <!-- femur -->
    <joint name="j_thigh_${side}${position}" type="revolute">
        <origin xyz="${coxa_length} 0.0 -0.025" rpy="-${pi/2} 0.0 0.0"/>
        <parent link="link_c1_${side}${position}"/>
        <child link="link_thigh_${side}${position}"/>
        <axis xyz="0.0 0.0 ${axis_femur}"/>
        <limit lower="${joint_lower_limit}" upper="${joint_upper_limit}" effort="${joint_effort}" velocity="${joint_velocity}"/>
    </joint>

    <transmission name="t_thigh_${side}${position}">
        <type>transmission_interface/SimpleTransmission</type>
        <joint name="j_thigh_${side}${position}">
            <hardwareInterface>EffortJointInterface</hardwareInterface>
        </joint>
        <actuator name="m_thigh_${side}${position}">
            <hardwareInterface>EffortJointInterface</hardwareInterface>
            <mechanicalReduction>1</mechanicalReduction>
        </actuator>
    </transmission>

    <link name="link_thigh_${side}${position}">
        <visual>
            <origin xyz="0.0 0.0 0.0" rpy="0.0 0.0 0.0"/>
            <geometry>
                <mesh filename="package://spider_description/meshes/xacro/femur.STL"/>
            </geometry>
            <material name="">
                <color rgba="0.7 0.7 0.7 1"/>
            </material>
        </visual>
        <collision>
            <origin xyz="0.0 0.0 0.0" rpy="0.0 0.0 0.0" />
            <geometry>
                <mesh filename="package://spider_description/meshes/xacro/femur.STL"/>
            </geometry>
            <material name="">
                <color rgba="0.7 0.7 0.7 1" />
            </material>
        </collision>
        <inertial>
            <origin xyz="0.0409997696348329 -4.30564251890919E-08 -0.0231455246060158" rpy="0.0 0.0 0.0" />
            <mass value="0.095338"/>
            <inertia
                ixx="1.5823E-05"
                ixy="-7.1837E-09"
                ixz="2.4429E-07"
                iyy="9.7493E-05"
                iyz="1.7728E-11"
                izz="9.2466E-05" />
        </inertial>
    </link>

    <!-- tibia -->
    <joint name="j_tibia_${side}${position}" type="revolute">
        <origin xyz="0.0 -${femur_length} 0.0" rpy="${pi} 0.0 0.0"/>
        <parent link="link_thigh_${side}${position}"/>
        <child link="link_tibia_${side}${position}"/>
        <axis xyz="0.0 0.0 ${axis_tibia}"/>
        <limit lower="${joint_lower_limit}" upper="${joint_upper_limit}" effort="${joint_effort}" velocity="${joint_velocity}"/>
    </joint>

    <transmission name="t_tibia_${side}${position}">
        <type>transmission_interface/SimpleTransmission</type>
        <joint name="j_tibia_${side}${position}">
            <hardwareInterface>EffortJointInterface</hardwareInterface>
        </joint>
        <actuator name="m_tibia_${side}${position}">
            <hardwareInterface>EffortJointInterface</hardwareInterface>
            <mechanicalReduction>1</mechanicalReduction>
        </actuator>
    </transmission>

    <link name="link_tibia_${side}${position}">
        <visual>
            <origin xyz="0.0 -0.0 0.0" rpy="0.0 0.0 0.0"/>
            <geometry>
                <mesh filename="package://spider_description/meshes/xacro/tibia.STL" />
            </geometry>
            <material name="">
                <color rgba="0.7 0.7 0.7 1"/>
            </material>
        </visual>
        <collision>
            <origin xyz="0.0 0.0 0.0" rpy="0.0 0.0 0.0" />
            <geometry>
                <mesh filename="package://spider_description/meshes/xacro/tibia.STL" />
            </geometry>
            <material name="">
                <color rgba="0.7 0.7 0.7 1" />
            </material>
        </collision>
        <inertial>
            <origin xyz="0.0582130929481518 -4.84132050920794E-07 -0.0240097551133858" rpy="0.0 0.0 0.0" />
            <mass value="0.027469"/>
            <inertia
                ixx="1.3791E-05"
                ixy="-1.8639E-09"
                ixz="2.7079E-09"
                iyy="8.6758E-05"
                iyz="1.5216E-13"
                izz="7.8702E-05" />
        </inertial>
    </link>




    </xacro:macro>


    <!-- Build robot model -->
    <xacro:leg side="r" position="r" x="-0.170" y="-0.110" angle="-${pi*3/4}" axis_femur="1" axis_tibia="1"/>
    <xacro:leg side="r" position="m" x="0.0" y="-0.1325" angle="-${pi/2}" axis_femur="1" axis_tibia="1"/>
    <xacro:leg side="r" position="f" x="0.1778" y="-0.110" angle="-${pi/4}" axis_femur="1" axis_tibia="1"/>

    <xacro:leg side="l" position="r" x="-0.170" y="0.110" angle="${pi*3/4}" axis_femur="-1" axis_tibia="-1"/>
    <xacro:leg side="l" position="m" x="0.0" y="0.1325" angle="${pi/2}" axis_femur="-1" axis_tibia="-1"/>
    <xacro:leg side="l" position="f" x="0.170" y="0.110" angle="${pi/4}" axis_femur="-1" axis_tibia="-1"/>




</robot>
